Workbook

Sheet Test Cases
A1: ID | B1: Module | C1: Title | D1: Type | E1: Priority | F1: Steps | G1: Test Data | H1: Expected Result | I1: Actual Result | J1: Status | K1: Evidence | L1: Notes | M1: Review
A2: TC-001 | B2: Booking | C2: Successful room reservation | D2: Positive | E2: High | F2: 1. Select a room and dates 2. Enter first and last name 3. Enter a valid email 4. Enter a phone number within the allowed length 5. Click Reserve Now | G2: Valid name, valid email, phone 11-21 digits | H2: Booking is accepted and a clear confirmation is shown | I2: Reported as accepted after entering the phone number in the required format. | J2: PASS | K2: https://drive.google.com/file/d/1hoxzxbmMg-PCvYAGtyb41rE_oqD9SkvS/view?usp=sharing | L2: The successful reservation not have the deateiles of bokking | M2: Notes text is outdated; evidence now attached
A3: TC-002 | B3: Booking | C3: Email field is required | D3: Negative | E3: High | F3: 1. Open booking form 2. Fill name and phone with valid data 3. Leave Email empty 4. Click Reserve Now | G3: Email = (empty) | H3: Booking is blocked and a validation message is shown | I3: Blocked to login and show error massege (must not be empty) | J3: PASS | K3: https://drive.google.com/file/d/1BjDsk42ONMVeprSOZHP95YYrXhxUPIM_/view?usp=sharing | L3: the error massege not clear
A4: TC-003 | B4: Booking | C4: Phone number minimum length | D4: Negative | E4: High | F4: 1. Open booking form 2. Fill other fields correctly 3. Enter a phone shorter than 11 digits 4. Click Reserve Now 5. Retry with a value in the 11-21 range | G4: Phone = 10 digits, then 21+ digits | H4: Short value is rejected with a message stating the length rule; in-range value is accepted | I4: The short phone number was rejected with a length message; a value in the allowed range was accepted. | J4: PASS | K4: https://drive.google.com/file/d/1vHAcXGGAA2VsUwEeSwzn9F4dBdD5ijrt/view?usp=sharing https://drive.google.com/file/d/1ekWbMd4_J1aFbL1Nw4J9GLposVEEbU1u/view?usp=sharing | M4: Actual written from the reported PASS; confirm it was executed; Evidence missing; Test Data says 21+ digits; steps and expected use 11. Confirm
A5: TC-004 | B5: Booking | C5: Booking date selection | D5: Positive | E5: High | F5: 1. Open room details 2. Select valid check-in and check-out dates 3. Observe selected dates in the calendar 4. Check the price summary and number of nights | G5: Any valid future range | H5: Selected dates, nights, and total price are reflected correctly | I5: the selected dates, number of nights and total price were reflected correctly. | J5: PASS | M5: Actual written from the reported PASS; confirm it was executed; Evidence missing
A6: TC-005 | B6: Booking | C6: Price calculation | D6: Positive | E6: High | F6: 1. Select a room with a known nightly price 2. Select a 1-night stay 3. Check the price summary and fees | G6: Room price per night as shown (e.g. 150), 1 night | H6: Total equals nightly price + fees shown on screen | I6: As expected: the total matched the nightly price plus the fees shown. | J6: PASS | L6: Verify the fee amounts on the live page; do not assume them. | M6: Actual written from the reported PASS; confirm it was executed; Evidence missing
A7: TC-006 | B7: Booking | C7: Submit empty form | D7: Negative | E7: High | F7: 1. Open booking form 2. Click Reserve Now without entering anything | G7: All fields empty | H7: Booking is blocked and validation messages appear for every required field | I7: error massege appear | J7: PASS | K7: https://drive.google.com/file/d/1rqGeyyRyECHOo4Pr3aoFEZHoeRfBdpFv/view?usp=sharing | L7: the error massege not clear for the empty feiled | M7: Evidence missing
A8: TC-007 | B8: Booking | C8: First name below minimum length | D8: Boundary | E8: Medium | F8: 1. Enter a 2-character first name 2. Fill other fields correctly 3. Click Reserve Now | G8: First name = 2 chars | H8: Rejected with a message about the allowed length | I8: error massege appear (size must be between 3 and 18) | J8: PASS | K8: https://drive.google.com/file/d/1Gto4Be2eTh8mdct1W-KDhHueqAA-J3j2/view?usp=sharing | L8: the error massege not clear for the empty feiled | M8: Evidence missing; Note about the empty field does not fit this case
A9: TC-008 | B9: Booking | C9: First name at minimum length | D9: Boundary | E9: Medium | F9: 1. Enter a 3-character first name 2. Fill other fields correctly 3. Click Reserve Now | G9: First name = 3 chars | H9: Booking accepted | I9: the booking accepted | J9: PASS | K9: https://drive.google.com/file/d/1hoxzxbmMg-PCvYAGtyb41rE_oqD9SkvS/view?usp=sharing | L9: the error massege not clear for the empty feiled | M9: Evidence missing; Note about the empty field does not fit this case
A10: TC-009 | B10: Booking | C10: First name maximum length | D10: Boundary | E10: Medium | F10: 1. Enter an 18-character first name, submit 2. Repeat with 19 characters | G10: First name = 18 chars, then 19 chars | H10: 18 accepted, 19 rejected | I10: the booking accepted 18 and rejectt 19 | J10: PASS | K10: https://drive.google.com/file/d/1nWPy0ULV4MxKSZYSa0ehUzxok_AwIOv5/view?usp=sharing | L10: the error massege not clear for the empty feiled | M10: Evidence missing; 19-character rejection not recorded
A11: TC-010 | B11: Booking | C11: Last name length limits | D11: Boundary | E11: Medium | F11: 1. Try last names of 2, 3, 30, and 31 characters with other fields valid | G11: Last name = 2 / 3 / 30 / 31 chars | H11: Limits are enforced consistently with clear messages | I11: the limitis is work good | J11: PASS | K11: https://drive.google.com/file/d/1ZCF2rgsQHvO2qTzvPnd1UtS2O7nXMXqb/view?usp=sharing // https://drive.google.com/file/d/1Kc6mzqoBQxZ2CfeOdn8ZqkkGBj16s0-A/view?usp=sharing | L11: Assumed limits; adjust to actual rule. | M11: Evidence missing; Only one of four lengths tried; Actual is in Arabic
A12: TC-011 | B12: Booking | C12: Phone minimum boundary | D12: Boundary | E12: High | F12: 1. Enter a 10-digit phone, submit 2. Repeat with 11 digits | G12: Phone = 10, then 11 digits | H12: 10 rejected, 11 accepted | I12: 10 digits rejected, 11 digits accepted. | J12: PASS | K12: https://drive.google.com/file/d/1ZKAcp4yhh-XAjVHHY_eKeymY-jib3yKa/view?usp=sharing | M12: Actual written from the reported PASS; confirm it was executed; Evidence missing
A13: TC-012 | B13: Booking | C13: Phone maximum boundary | D13: Boundary | E13: High | F13: 1. Enter a 21-digit phone, submit 2. Repeat with 22 digits | G13: Phone = 21, then 22 digits | H13: 21 accepted, 22 rejected | I13: 21 digits accepted, 22 digits rejected. | J13: PASS | K13: https://drive.google.com/file/d/1lM0qtyNzGtbpqe461cqcdJwrDFTXQHdz/view?usp=sharing | M13: Actual written from the reported PASS; confirm it was executed; Evidence missing
A14: TC-013 | B14: Booking | C14: Phone with letters or symbols | D14: Negative | E14: Medium | F14: 1. Enter a phone containing letters/symbols 2. Fill other fields correctly 3. Click Reserve Now | G14: Phone = abc12345678 | H14: Rejected or a suitable error shown; if accepted, log as an observation | I14: بيقبلها بس ما عندي سكرين | J14: FAIL | M14: Add evidence (screenshot); Actual is in Arabic
A15: TC-014 | B15: Booking | C15: Invalid email formats | D15: Negative | E15: High | F15: 1. Try each invalid email, one at a time, with other fields valid | G15: test | test@ | test@.com | a b@c.com | H15: Every invalid format is rejected | I15: rejectesd with error massege | J15: PASS | K15: https://drive.google.com/file/d/12ex_oNSYRJrNoTV0OU2aa0IuXPOMi6F1/view?usp=sharing | M15: Evidence missing
A16: TC-015 | B16: Booking | C16: Leading/trailing spaces in fields | D16: Boundary | E16: Low | F16: 1. Enter name, email, and phone with leading/trailing spaces 2. Submit | G16: Fields padded with spaces | H16: Handled gracefully (trimmed and accepted, or rejected clearly) | I16: بيقبلها لو حطينا رقم في مسافة بيكون نفس العدد المطلوب ما بيعنل trime | J16: FAIL | M16: Add evidence (screenshot); Actual is in Arabic; Evidence cell holds the word trim
A17: TC-016 | B17: Booking | C17: Check-out before check-in | D17: Negative | E17: High | F17: 1. Try to select a check-out date earlier than check-in | G17: Check-out < check-in | H17: The system prevents selecting such dates | I17: accepted whev check out < check in | J17: FAIL | K17: https://drive.google.com/file/d/1Ka2HsuKuvCgX_rTZwYVrPD5PaspxXCea/view?usp=sharing | M17: Add evidence (screenshot); Actual is in Arabic
A18: TC-017 | B18: Booking | C18: Past dates | D18: Negative | E18: High | F18: 1. Try to select a date earlier than today | G18: A date in the past | H18: Past dates are not selectable | I18: accepted | J18: FAIL | K18: https://drive.google.com/file/d/17mO7Q3_C69bDAugMOCD9owcUw37FsPuN/view?usp=sharing | M18: Add evidence (screenshot)
A19: TC-018 | B19: Booking | C19: Overlapping booking on the same room | D19: Negative | E19: High | F19: 1. Book a room for a date range 2. Try to book the same room for an overlapping range | G19: Overlapping ranges | H19: Second booking is rejected with a clear message | I19: بيقبل عادي | J19: FAIL | K19: need vidio | M19: Add evidence (screenshot); Actual is in Arabic
A20: TC-019 | B20: Booking | C20: Back-to-back booking without overlap | D20: Boundary | E20: Medium | F20: 1. Book a room 2. Book the same room starting on the previous check-out day | G20: Check-in = previous check-out | H20: Accepted (verify how the changeover day is handled) | J20: PASS | M20: Actual written from the reported PASS; confirm it was executed; Evidence missing
A21: TC-020 | B21: Booking | C21: Double-click on Reserve Now | D21: Negative | E21: Medium | F21: 1. Fill the form with valid data 2. Double-click Reserve Now quickly | G21: Valid data | H21: Only one booking is created | I21: As expected: only one booking was created. | J21: PASS | M21: Actual written from the reported PASS; confirm it was executed; Evidence missing
A22: TC-021 | B22: Booking | C22: Cancel booking form | D22: Positive | E22: Low | F22: 1. Open the form and enter some data 2. Click Cancel | G22: Partial data | H22: Returns to the calendar with no booking created and data not saved | I22: As expected: returned to the calendar; no booking created and data not saved. | J22: PASS | M22: Actual written from the reported PASS; confirm it was executed; Evidence missing
A23: TC-022 | B23: Booking | C23: Search with check-out before check-in | D23: Negative | E23: High | F23: 1. On home page set Check Out earlier than Check In 2. Click Check Availability | G23: Check In 28/10/2026, Check Out 25/10/2026 | H23: A warning appears and no rooms are offered | I23: No warning; all 3 rooms offered, Book now links carry the reversed dates | J23: FAIL | K23: https://drive.google.com/file/d/1Ka2HsuKuvCgX_rTZwYVrPD5PaspxXCea/view?usp=sharing | L23: Leads into TC-035 and TC-036
A24: TC-023 | B24: Booking | C24: No negative price for reversed dates | D24: Negative | E24: High | F24: 1. Follow a Book now link from TC-034 2. Check the price summary | G24: Reversed dates | H24: Dates refused; no negative price shown | I24: £100 x -3 nights … Total £-260 shown, Reserve Now still active | J24: FAIL | L24: Also seen as Total £-160 (run 13268)
A25: TC-024 | B25: Booking | C25: Booking calendar opens on the chosen month | D25: Positive | E25: Low | F25: 1. Search dates 2 months ahead 2. Click Book now 3. Look at the calendar | G25: 8–10 Dec 2026 | H25: Calendar opens on December with the nights marked | I25: Opens on October; nights marked only after clicking Next twice | J25: FAIL | K25: https://drive.google.com/file/d/1CgNKMPlJSgbeQlWxdH6_76NivSjDzQb3/view?usp=sharing
A26: TC-025 | B26: Booking | C26: Confirmation shows reference and total | D26: Positive | E26: Low | F26: 1. Complete a valid booking 2. Read the confirmation | G26: Valid booking | H26: Booking reference, room and total shown | I26: Only "Booking Confirmed" and the two dates | J26: FAIL | K26: https://drive.google.com/file/d/1hoxzxbmMg-PCvYAGtyb41rE_oqD9SkvS/view?usp=sharing | L26: Total (£340) was shown a moment before, then gone
A27: TC-026 | B27: Booking | C27: Booked room no longer offered for same dates | D27: Positive | E27: High | F27: 1. Book a room 2. Search the same dates again | G27: Double, 8–10 Dec 2026 | H27: Booked room not offered | I27: Double no longer offered for those dates | J27: FAIL | K27: need vidio | L27: Run right after booking — demo resets data | M27: ID corrected (typo)
A28: TC-027 | B28: Booking | C28: Fully booked dates show a clear "no rooms" message | D28: Negative | E28: Medium | F28: 1. Search a range where every room is booked | G28: Fully booked range | H28: Clear "no rooms available" message | I28: No rooms listed (run 13269), but message wording not confirmed; run 13272 could not make a fully booked range | J28: BLOCKED | K28: — | L28: Shared demo; retry on a private environment | M28: BLOCKED: add retry plan or leave as an environment limitation
A29: TC-028 | B29: Booking | C29: Multi-night total price | D29: Positive | E29: High | F29: 1. Select a 2-night stay 2. Check the price summary | G29: Double £150, 2 nights | H29: Total = nights × price + fees | I29: £150 × 2 = £300 + £25 + £15 = £340 | J29: PASS
A30: TC-029 | B30: Booking | C30: First name trims leading and trailing spaces | D30: Functional | E30: Medium | F30: 1. Enter a first name with spaces before and after it. 2. Fill in the other fields correctly. 3. Click Reserve Now. | G30: First name = Ali | H30: Spaces are trimmed, and the first name is validated using the actual name length (3 characters). Booking is accepted. | I30: accepted not trim | J30: FAIL | M30: Add evidence (screenshot); Renumbered (was a duplicate TC-011)
A31: TC-030 | B31: Booking | C31: Last name trims leading and trailing spaces | D31: Functional | E31: Medium | F31: 1. Enter a last name with spaces before and after it. 2. Fill in the other fields correctly. 3. Click Reserve Now. | G31: Last name = Ahmad | H31: Spaces are trimmed and are not counted toward the last name length. The booking is accepted if the trimmed name meets the validation rules. | I31: accepted not trim | J31: FAIL | M31: Add evidence (screenshot); Renumbered (was a duplicate TC-012)
A32: TC-031 | B32: Booking | C32: Room cards show correct information | D32: Positive | E32: Medium | F32: 1. Open the home page rooms section 2. For each room type check name, price per night, description and amenities 3. Open each room's details page 4. Check the Reserve Now button | G32: All room types shown | H32: Information is complete and consistent between the list, the details page and the admin room data; Reserve Now opens the booking flow | J32: PASS | L32: Added to close a coverage gap (room information display). | M32: New case: not yet executed
A33: TC-032 | B33: Booking | C33: Valid availability search | D33: Positive | E33: High | F33: 1. On the home page choose valid Check In and Check Out dates 2. Click Check Availability 3. Follow a Book now link | G33: Check In and Check Out a few days ahead | H33: Only available rooms are listed and the chosen dates are carried to the booking page | J33: BLOCKED | L33: becouse there is many pepole are working in the website | M33: New case: not yet executed
A34: TC-033
A35: TC-034 | B35: Contact | C35: Successful contact message | D35: Positive | E35: High | F35: 1. Fill name, email, phone, subject, and message with valid data 2. Submit | G35: Valid data in all fields | H35: A clear confirmation is shown | I35: As expected: a confirmation was shown after sending valid data. | J35: PASS | K35: https://drive.google.com/file/d/1vDUxShXRsPlthScgjFtkVYgWZ3-YTOBf/view?usp=sharing | M35: Actual written from the reported PASS; confirm it was executed; Evidence missing
A36: TC-035 | B36: Contact | C36: Empty contact form | D36: Negative | E36: High | F36: 1. Submit the contact form with all fields empty | G36: All fields empty | H36: Validation messages appear for each required field | I36: As expected: validation messages were shown for the required fields. | J36: PASS | K36: https://drive.google.com/file/d/1E81aPkzNVs6rdQ2fpOjlXlFAYSkzMNfJ/view?usp=sharing | M36: Actual written from the reported PASS; confirm it was executed; Evidence missing
A37: TC-036 | B37: Contact | C37: Subject and message length limits | D37: Boundary | E37: Medium | F37: 1. Try a very short subject and message 2. Try very long values | G37: Short and long strings | H37: Limits are enforced with clear error messages | I37: As expected: the limits were enforced with error messages. | J37: PASS | L37: Confirm real limits from the messages shown. | M37: Actual written from the reported PASS; confirm it was executed; Evidence missing
A38: TC-037 | B38: Contact | C38: Double-click Submit sends one message | D38: Negative | E38: Medium | F38: 1. Fill contact form validly 2. Double-click Submit 3. Check owner Messages | G38: Valid data | H38: One message arrives | I38: Two identical messages; unread count goes up by 2 | J38: PASS | K38: https://drive.google.com/file/d/1vDUxShXRsPlthScgjFtkVYgWZ3-YTOBf/view?usp=sharing | M38: Status conflicts with Actual (two messages sent but marked PASS)
A39: TC-038 | B39: Contact | C39: Phone with letters on contact form | D39: Negative | E39: Medium | F39: 1. Enter a letters-only phone 2. Submit | G39: Phone = abcdefghijk | H39: Rejected with a clear message | I39: Accepted; owner sees "Phone: abcdefghijk" | J39: FAIL
A40: TC-039 | B40: Contact | C40: Invalid email on contact form | D40: Negative | E40: High | F40: 1. Enter a badly formatted email 2. Submit | G40: Malformed email | H40: Rejected; typed data kept | I40: Rejected and typed data kept | J40: PASS | L40: Runs did not list which formats were tried
...

Sheet Summary
A1: Test Execution Summary
A3: Status | B3: Count | C3: % of total
A4: PASS | B4: =COUNTIF('Test Cases'!$J$2:$J$200,A4) -> 39 | C4: =IF($B$8=0,0,B4/$B$8) -> 0.65
A5: FAIL | B5: =COUNTIF('Test Cases'!$J$2:$J$200,A5) -> 19 | C5: =IF($B$8=0,0,B5/$B$8) -> 0.31666667
A6: BLOCKED | B6: =COUNTIF('Test Cases'!$J$2:$J$200,A6) -> 2 | C6: =IF($B$8=0,0,B6/$B$8) -> 0.033333333
A7: NOT RUN | B7: =COUNTIF('Test Cases'!$J$2:$J$200,A7) -> 0 | C7: =IF($B$8=0,0,B7/$B$8) -> 0
A8: Total | B8: =SUM(B4:B7) -> 60 | C8: =SUM(C4:C7) -> 1
A9: Executed (PASS + FAIL + BLOCKED) | B9: =B4+B5+B6 -> 60 | C9: =IF(B8=0,0,B9/B8) -> 1
A10: Pass rate of executed (PASS / (PASS+FAIL)) | B10: =IF(B4+B5=0,0,B4/(B4+B5)) -> 0.67241379
A12: By module
A13: Module | B13: PASS | C13: FAIL | D13: BLOCKED | E13: NOT RUN | F13: Total
A14: Booking | B14: =COUNTIFS('Test Cases'!$B$2:$B$200,$A14,'Test Cases'!$J$2:$J$200,"PASS") -> 18 | C14: =COUNTIFS('Test Cases'!$B$2:$B$200,$A14,'Test Cases'!$J$2:$J$200,"FAIL") -> 12 | D14: =COUNTIFS('Test Cases'!$B$2:$B$200,$A14,'Test Cases'!$J$2:$J$200,"BLOCKED") -> 2 | E14: =COUNTIFS('Test Cases'!$B$2:$B$200,$A14,'Test Cases'!$J$2:$J$200,"NOT RUN") -> 0 | F14: =SUM(B14:E14) -> 32
A15: Contact | B15: =COUNTIFS('Test Cases'!$B$2:$B$200,$A15,'Test Cases'!$J$2:$J$200,"PASS") -> 7 | C15: =COUNTIFS('Test Cases'!$B$2:$B$200,$A15,'Test Cases'!$J$2:$J$200,"FAIL") -> 1 | D15: =COUNTIFS('Test Cases'!$B$2:$B$200,$A15,'Test Cases'!$J$2:$J$200,"BLOCKED") -> 0 | E15: =COUNTIFS('Test Cases'!$B$2:$B$200,$A15,'Test Cases'!$J$2:$J$200,"NOT RUN") -> 0 | F15: =SUM(B15:E15) -> 8
A16: Admin | B16: =COUNTIFS('Test Cases'!$B$2:$B$200,$A16,'Test Cases'!$J$2:$J$200,"PASS") -> 10 | C16: =COUNTIFS('Test Cases'!$B$2:$B$200,$A16,'Test Cases'!$J$2:$J$200,"FAIL") -> 4 | D16: =COUNTIFS('Test Cases'!$B$2:$B$200,$A16,'Test Cases'!$J$2:$J$200,"BLOCKED") -> 0 | E16: =COUNTIFS('Test Cases'!$B$2:$B$200,$A16,'Test Cases'!$J$2:$J$200,"NOT RUN") -> 0 | F16: =SUM(B16:E16) -> 14
A17: Navigation | B17: =COUNTIFS('Test Cases'!$B$2:$B$200,$A17,'Test Cases'!$J$2:$J$200,"PASS") -> 1 | C17: =COUNTIFS('Test Cases'!$B$2:$B$200,$A17,'Test Cases'!$J$2:$J$200,"FAIL") -> 2 | D17: =COUNTIFS('Test Cases'!$B$2:$B$200,$A17,'Test Cases'!$J$2:$J$200,"BLOCKED") -> 0 | E17: =COUNTIFS('Test Cases'!$B$2:$B$200,$A17,'Test Cases'!$J$2:$J$200,"NOT RUN") -> 0 | F17: =SUM(B17:E17) -> 3
A18: Exploratory | B18: =COUNTIFS('Test Cases'!$B$2:$B$200,$A18,'Test Cases'!$J$2:$J$200,"PASS") -> 3 | C18: =COUNTIFS('Test Cases'!$B$2:$B$200,$A18,'Test Cases'!$J$2:$J$200,"FAIL") -> 0 | D18: =COUNTIFS('Test Cases'!$B$2:$B$200,$A18,'Test Cases'!$J$2:$J$200,"BLOCKED") -> 0 | E18: =COUNTIFS('Test Cases'!$B$2:$B$200,$A18,'Test Cases'!$J$2:$J$200,"NOT RUN") -> 0 | F18: =SUM(B18:E18) -> 3
A19: By type
A20: Positive | B20: =COUNTIF('Test Cases'!$D$2:$D$200,A20) -> 24
A21: Negative | B21: =COUNTIF('Test Cases'!$D$2:$D$200,A21) -> 22
A22: Boundary | B22: =COUNTIF('Test Cases'!$D$2:$D$200,A22) -> 9
A23: Functional | B23: =COUNTIF('Test Cases'!$D$2:$D$200,A23) -> 2
A24: Exploratory | B24: =COUNTIF('Test Cases'!$D$2:$D$200,A24) -> 3
A26: Test date: | B26: (fill in)
A27: Environment: | B27: (browser, OS, app URL)
A28: Tester: | B28: Haifa Samir
A30: Open Review Flags and the Review column on the Test Cases sheet before submission.

Sheet Coverage Map
A1: Coverage Map: system areas vs test cases
A3: Area | B3: Test cases | C3: Coverage | D3: Comment
A4: Room browsing and room information | B4: TC-060 | C4: Covered (new, not run) | D4: Room cards, details page and Reserve Now entry point had no case before
A5: Availability search (home page) | B5: TC-034, 039, 040, 061 | C5: Covered | D5: Positive search added; fully-booked message still blocked (TC-040)
A6: Booking form validation | B6: TC-002, 003, 006-015, 058, 059 | C6: Covered | D6: Names, email, phone boundaries and trimming
A7: Booking dates and rules | B7: TC-016, 017, 018, 019, 035, 037 | C7: Covered | D7: Reversed, past, overlapping and back-to-back dates
A8: Price and confirmation | B8: TC-004, 005, 038, 041 | C8: Covered | D8: Single and multi-night totals, confirmation content
A9: Booking error handling and double submit | B9: TC-020, 036 | C9: Covered
A10: Contact form | B10: TC-022, 023, 024, 042-046 | C10: Covered | D10: Validation, double submit, owner reading
A11: Admin login and access control | B11: TC-025, 026, 030, 062 | C11: Covered | D11: Logout and direct-URL access are new, not run
A12: Admin rooms management | B12: TC-029, 047, 048, 049, 050, 063 | C12: Covered | D12: Create, duplicate, validation messages, price update; edit is new
A13: Admin messages | B13: TC-028, 045, 046 | C13: Covered
A14: Admin bookings report | B14: TC-027, 053 | C14: Covered
A15: Admin branding | B15: TC-051 | C15: Partial | D15: Blocked by a defect; changing branding values not tested
A16: Navigation and static pages | B16: TC-055, 056, 057 | C16: Covered | D16: TC-057 not actually tested
A17: Responsive, refresh, special characters | B17: TC-031, 032, 033 | C17: Covered | D17: Results lack actual text and evidence
A18: Accessibility and keyboard use | B18: none | C18: Gap | D18: Low priority; optional to add
A19: API (services layer) | B19: none | C19: Out of scope | D19: Excluded by decision; listed as a risk in the strategy
A20: Performance and penetration testing | B20: none | C20: Out of scope | D20: Excluded in the strategy

Sheet Review Flags
A1: Items to fix before submission
A3: Priority | B3: Test cases | C3: Issue | D3: What to do
A4: High | B4: TC-036, TC-042, TC-057 | C4: Status conflicts with the actual result (PASS while the actual describes a failure or no test) | D4: Set the status that matches what you observed: FAIL for TC-036 and TC-042 if the actual is right, NOT RUN for TC-057
A5: High | B5: TC-003, TC-004, TC-005, TC-011, TC-012, TC-019, TC-020, TC-021, TC-022, TC-023, TC-024, TC-025, TC-026, TC-027, TC-028, TC-029, TC-031, TC-032, TC-033 | C5: Actual result written from the reported PASS status, not from observation | D5: Confirm each was really executed and replace with what you saw (messages, values), or set NOT RUN
A6: High | B6: TC-003, TC-004, TC-005, TC-006, TC-007, TC-008, TC-009, TC-010, TC-011, TC-012, TC-014, TC-019, TC-020, TC-021, TC-022, TC-023, TC-024, TC-025, TC-026, TC-027, TC-028, TC-029, TC-031, TC-032, TC-033 | C6: PASS with no evidence | D6: Add a screenshot link for each, or set NOT RUN
A7: High | B7: TC-013, TC-015, TC-016, TC-017, TC-018, TC-058, TC-059 | C7: FAIL without evidence | D7: Reproduce and attach a screenshot before reporting as a defect
A8: Medium | B8: TC-009, TC-010 | C8: Boundary cases only partly executed | D8: Record each length tried (18/19 characters; 2/3/30/31 characters)
A9: Medium | B9: TC-003 | C9: Test Data (21+ digits) does not match the steps and expected result (11 digits) | D9: Correct the test data
A10: Medium | B10: TC-013, TC-015, TC-016, TC-010, TC-018 | C10: Actual results written in Arabic | D10: Rewrite in English for the submission
A11: Medium | B11: Runs 13268 to 13277 | C11: Evidence cites run numbers | D11: Explain what a run is in the README, or attach screenshots, so a reviewer can trace them
A12: Medium | B12: TC-001, TC-002 | C12: Drive links | D12: Check the links open for anyone with the link
A13: Low | B13: TC-007, TC-008, TC-009 | C13: Same note about the empty field copied into three cases | D13: Replace with a note that fits each case
A14: Low | B14: TC-052, TC-054 | C14: IDs missing from the sheet (TC-051 says it blocks TC-052) | D14: Add the cases or note that they were dropped
... A16: Info | B16: TC-030, 060, 061, 062, 063 | C16: New cases added to close coverage gaps, all NOT RUN | D16: Run them or delete the ones you do not want
